  {
    "registryname": "blastfurnace_titanium", 
    "localizedname": "Titanium Blast Furnace", 
    "requires-blueprint": true, 
    "color": "DCA0F0", 
    "parts": [
        {
            "x": 0,
            "y": 2,
            "z": 2,
            "elements": [
                "ct_machine_frame_titanium"
            ]
        },
        {
            "x": 1,
            "y": 2,
            "z": 1,
            "elements": [
                "ct_machine_frame_titanium"
            ]
        },
        {
            "x": -1,
            "y": 0,
            "z": 0,
            "elements": [
                "ct_machine_frame_titanium",
                "modularmachinery:blockfluidinputhatch",
                "modularmachinery:blockinputbus",
                "modularmachinery:blockoutputbus"
            ]
        },
        {
            "x": -1,
            "y": 0,
            "z": 1,
            "elements": [
                "ct_machine_frame_titanium",
                "modularmachinery:blockfluidinputhatch",
                "modularmachinery:blockinputbus",
                "modularmachinery:blockoutputbus"
            ]
        },
        {
            "x": 0,
            "y": 0,
            "z": 1,
            "elements": [
                "minecraft:lava@0"
            ]
        },
        {
            "x": 1,
            "y": 2,
            "z": 2,
            "elements": [
                "ct_machine_frame_titanium"
            ]
        },
        {
            "x": 1,
            "y": 0,
            "z": 0,
            "elements": [
                "ct_machine_frame_titanium",
                "modularmachinery:blockfluidinputhatch",
                "modularmachinery:blockinputbus",
                "modularmachinery:blockoutputbus"
            ]
        },
        {
            "x": -1,
            "y": 0,
            "z": 2,
            "elements": [
                "ct_machine_frame_titanium",
                "modularmachinery:blockfluidinputhatch",
                "modularmachinery:blockinputbus",
                "modularmachinery:blockoutputbus"
            ]
        },
        {
            "x": 1,
            "y": 0,
            "z": 1,
            "elements": [
                "ct_machine_frame_titanium",
                "modularmachinery:blockfluidinputhatch",
                "modularmachinery:blockinputbus",
                "modularmachinery:blockoutputbus"
            ]
        },
        {
            "x": 0,
            "y": 0,
            "z": 2,
            "elements": [
                "ct_machine_frame_titanium",
                "modularmachinery:blockfluidinputhatch",
                "modularmachinery:blockinputbus",
                "modularmachinery:blockoutputbus"
            ]
        },
        {
            "x": 1,
            "y": 0,
            "z": 2,
            "elements": [
                "ct_machine_frame_titanium",
                "modularmachinery:blockfluidinputhatch",
                "modularmachinery:blockinputbus",
                "modularmachinery:blockoutputbus"
            ]
        },
        {
            "x": 1,
            "y": -1,
            "z": 0,
            "elements": [
                "ct_machine_frame_titanium"
            ]
        },
        {
            "x": -1,
            "y": 1,
            "z": 0,
            "elements": [
                "ct_machine_frame_titanium"
            ]
        },
        {
            "x": 0,
            "y": -1,
            "z": 0,
            "elements": [
                "ct_machine_frame_titanium"
            ]
        },
        {
            "x": 0,
            "y": 1,
            "z": 0,
            "elements": [
                "ct_machine_frame_titanium"
            ]
        },
        {
            "x": -1,
            "y": 1,
            "z": 1,
            "elements": [
                "ct_machine_frame_titanium"
            ]
        },
        {
            "x": -1,
            "y": -1,
            "z": 0,
            "elements": [
                "ct_machine_frame_titanium"
            ]
        },
        {
            "x": 0,
            "y": 1,
            "z": 1,
            "elements": [
                "minecraft:lava@0"
            ]
        },
        {
            "x": 1,
            "y": 1,
            "z": 0,
            "elements": [
                "ct_machine_frame_titanium"
            ]
        },
        {
            "x": -1,
            "y": 1,
            "z": 2,
            "elements": [
                "ct_machine_frame_titanium"
            ]
        },
        {
            "x": 0,
            "y": 1,
            "z": 2,
            "elements": [
                "ct_machine_frame_titanium"
            ]
        },
        {
            "x": 1,
            "y": 1,
            "z": 1,
            "elements": [
                "ct_machine_frame_titanium"
            ]
        },
        {
            "x": -1,
            "y": -1,
            "z": 1,
            "elements": [
                "ct_machine_frame_titanium"
            ]
        },
        {
            "x": 1,
            "y": 1,
            "z": 2,
            "elements": [
                "ct_machine_frame_titanium"
            ]
        },
        {
            "x": -1,
            "y": -1,
            "z": 2,
            "elements": [
                "ct_machine_frame_titanium"
            ]
        },
        {
            "x": 0,
            "y": -1,
            "z": 1,
            "elements": [
                "ct_machine_frame_titanium"
            ]
        },
        {
            "x": 0,
            "y": -1,
            "z": 2,
            "elements": [
                "ct_machine_frame_titanium"
            ]
        },
        {
            "x": 1,
            "y": -1,
            "z": 1,
            "elements": [
                "ct_machine_frame_titanium"
            ]
        },
        {
            "x": 1,
            "y": -1,
            "z": 2,
            "elements": [
                "ct_machine_frame_titanium"
            ]
        },
        {
            "x": -1,
            "y": 2,
            "z": 0,
            "elements": [
                "ct_machine_frame_titanium"
            ]
        },
        {
            "x": -1,
            "y": 2,
            "z": 1,
            "elements": [
                "ct_machine_frame_titanium"
            ]
        },
        {
            "x": 0,
            "y": 2,
            "z": 0,
            "elements": [
                "ct_machine_frame_titanium"
            ]
        },
        {
            "x": 0,
            "y": 2,
            "z": 1,
            "elements": [
                "modularmachinery:blockfluidoutputhatch"
            ]
        },
        {
            "x": -1,
            "y": 2,
            "z": 2,
            "elements": [
                "ct_machine_frame_titanium"
            ]
        },
        {
            "x": 1,
            "y": 2,
            "z": 0,
            "elements": [
                "ct_machine_frame_titanium"
            ]
        }
    ]}