{
    "registryname": "chemical_washer_aluminium", 
    "localizedname": "Aluminium Chemical Washer", 
    "requires-blueprint": true, 
    "color": "80C8F0",  
    "parts": [
        {
            "x": -1,
            "y": 0,
            "z": 0,
            "elements": "ct_machine_frame_aluminium"
        },
        {
            "x": -1,
            "y": 0,
            "z": 1,
            "elements": [
                "minecraft:glass@0",
                "modularmachinery:blockinputbus",
                "modularmachinery:blockenergyinputhatch",
                "modularmachinery:blockfluidinputhatch",
                "modularmachinery:blockoutputbus"
            ]
        },
        {
            "x": 0,
            "y": 0,
            "z": 1,
            "elements": [
                "minecraft:water@0"
            ]
        },
        {
            "x": 1,
            "y": 0,
            "z": 0,
            "elements": "ct_machine_frame_aluminium"
        },
        {
            "x": -1,
            "y": 0,
            "z": 2,
            "elements": [
                "minecraft:glass@0",
                "modularmachinery:blockinputbus",
                "modularmachinery:blockenergyinputhatch",
                "modularmachinery:blockfluidinputhatch",
                "modularmachinery:blockoutputbus"
            ]
        },
        {
            "x": 1,
            "y": 0,
            "z": 1,
            "elements": [
                "minecraft:glass@0",
                "modularmachinery:blockinputbus",
                "modularmachinery:blockenergyinputhatch",
                "modularmachinery:blockfluidinputhatch",
                "modularmachinery:blockoutputbus"
            ]
        },
        {
            "x": 0,
            "y": 0,
            "z": 2,
            "elements": [
                "minecraft:water@0"
            ]
        },
        {
            "x": -1,
            "y": 0,
            "z": 3,
            "elements": "ct_machine_frame_aluminium"
        },
        {
            "x": 0,
            "y": 0,
            "z": 3,
            "elements": [
                "minecraft:glass@0",
                "modularmachinery:blockinputbus",
                "modularmachinery:blockenergyinputhatch",
                "modularmachinery:blockfluidinputhatch",
                "modularmachinery:blockoutputbus"
            ]
        },
        {
            "x": 1,
            "y": 0,
            "z": 2,
            "elements": [
                "minecraft:glass@0",
                "modularmachinery:blockinputbus",
                "modularmachinery:blockenergyinputhatch",
                "modularmachinery:blockfluidinputhatch",
                "modularmachinery:blockoutputbus"
            ]
        },
        {
            "x": 1,
            "y": 0,
            "z": 3,
            "elements": "ct_machine_frame_aluminium"
        },
        {
            "x": 1,
            "y": -1,
            "z": 0,
            "elements": "ct_machine_frame_aluminium"
        },
        {
            "x": 0,
            "y": -1,
            "z": 0,
            "elements": "ct_machine_frame_aluminium"
        },
        {
            "x": -1,
            "y": 1,
            "z": 0,
            "elements": "ct_machine_frame_aluminium"
        },
        {
            "x": 0,
            "y": 1,
            "z": 0,
            "elements": "ct_machine_frame_aluminium"
        },
        {
            "x": -1,
            "y": -1,
            "z": 0,
            "elements": "ct_machine_frame_aluminium"
        },
        {
            "x": -1,
            "y": 1,
            "z": 1,
            "elements": "ct_machine_frame_aluminium"
        },
        {
            "x": 0,
            "y": 1,
            "z": 1,
            "elements": [
                "minecraft:glass@0",
                "modularmachinery:blockinputbus",
                "modularmachinery:blockenergyinputhatch",
                "modularmachinery:blockfluidinputhatch",
                "modularmachinery:blockoutputbus"
            ]
        },
        {
            "x": 1,
            "y": 1,
            "z": 0,
            "elements": "ct_machine_frame_aluminium"
        },
        {
            "x": -1,
            "y": 1,
            "z": 2,
            "elements": "ct_machine_frame_aluminium"
        },
        {
            "x": 0,
            "y": 1,
            "z": 2,
            "elements": [
                "minecraft:glass@0",
                "modularmachinery:blockinputbus",
                "modularmachinery:blockenergyinputhatch",
                "modularmachinery:blockfluidinputhatch",
                "modularmachinery:blockoutputbus"
            ]
        },
        {
            "x": 1,
            "y": 1,
            "z": 1,
            "elements": "ct_machine_frame_aluminium"
        },
        {
            "x": -1,
            "y": -1,
            "z": 1,
            "elements": "ct_machine_frame_aluminium"
        },
        {
            "x": -1,
            "y": 1,
            "z": 3,
            "elements": "ct_machine_frame_aluminium"
        },
        {
            "x": 0,
            "y": 1,
            "z": 3,
            "elements": "ct_machine_frame_aluminium"
        },
        {
            "x": 1,
            "y": 1,
            "z": 2,
            "elements": "ct_machine_frame_aluminium"
        },
        {
            "x": 0,
            "y": -1,
            "z": 1,
            "elements": "ct_agitator_aluminium"
        },
        {
            "x": -1,
            "y": -1,
            "z": 2,
            "elements": "ct_machine_frame_aluminium"
        },
        {
            "x": 1,
            "y": 1,
            "z": 3,
            "elements": "ct_machine_frame_aluminium"
        },
        {
            "x": 0,
            "y": -1,
            "z": 2,
            "elements": "ct_agitator_aluminium"
        },
        {
            "x": 1,
            "y": -1,
            "z": 1,
            "elements": "ct_machine_frame_aluminium"
        },
        {
            "x": -1,
            "y": -1,
            "z": 3,
            "elements": "ct_machine_frame_aluminium"
        },
        {
            "x": 1,
            "y": -1,
            "z": 2,
            "elements": "ct_machine_frame_aluminium"
        },
        {
            "x": 0,
            "y": -1,
            "z": 3,
            "elements": "ct_machine_frame_aluminium"
        },
        {
            "x": 1,
            "y": -1,
            "z": 3,
            "elements": "ct_machine_frame_aluminium"
        }
    ]}