{
    "registryname": "chemical_washer_steel", 
    "localizedname": "Steel Chemical Washer", 
    "requires-blueprint": true, 
    "color": "4E4E4E",  
    "parts": [
        {
            "x": -1,
            "y": 0,
            "z": 0,
            "elements": "ct_machine_frame_steel"
        },
        {
            "x": -1,
            "y": 0,
            "z": 1,
            "elements": [
                "minecraft:glass@0",
                "modularmachinery:blockinputbus",
                "modularmachinery:blockenergyinputhatch",
                "modularmachinery:blockfluidinputhatch",
                "modularmachinery:blockoutputbus"
            ]
        },
        {
            "x": 0,
            "y": 0,
            "z": 1,
            "elements": [
                "minecraft:water@0"
            ]
        },
        {
            "x": 1,
            "y": 0,
            "z": 0,
            "elements": "ct_machine_frame_steel"
        },
        {
            "x": -1,
            "y": 0,
            "z": 2,
            "elements": [
                "minecraft:glass@0",
                "modularmachinery:blockinputbus",
                "modularmachinery:blockenergyinputhatch",
                "modularmachinery:blockfluidinputhatch",
                "modularmachinery:blockoutputbus"
            ]
        },
        {
            "x": 1,
            "y": 0,
            "z": 1,
            "elements": [
                "minecraft:glass@0",
                "modularmachinery:blockinputbus",
                "modularmachinery:blockenergyinputhatch",
                "modularmachinery:blockfluidinputhatch",
                "modularmachinery:blockoutputbus"
            ]
        },
        {
            "x": 0,
            "y": 0,
            "z": 2,
            "elements": [
                "minecraft:water@0"
            ]
        },
        {
            "x": -1,
            "y": 0,
            "z": 3,
            "elements": "ct_machine_frame_steel"
        },
        {
            "x": 0,
            "y": 0,
            "z": 3,
            "elements": [
                "minecraft:glass@0",
                "modularmachinery:blockinputbus",
                "modularmachinery:blockenergyinputhatch",
                "modularmachinery:blockfluidinputhatch",
                "modularmachinery:blockoutputbus"
            ]
        },
        {
            "x": 1,
            "y": 0,
            "z": 2,
            "elements": [
                "minecraft:glass@0",
                "modularmachinery:blockinputbus",
                "modularmachinery:blockenergyinputhatch",
                "modularmachinery:blockfluidinputhatch",
                "modularmachinery:blockoutputbus"
            ]
        },
        {
            "x": 1,
            "y": 0,
            "z": 3,
            "elements": "ct_machine_frame_steel"
        },
        {
            "x": 1,
            "y": -1,
            "z": 0,
            "elements": "ct_machine_frame_steel"
        },
        {
            "x": 0,
            "y": -1,
            "z": 0,
            "elements": "ct_machine_frame_steel"
        },
        {
            "x": -1,
            "y": 1,
            "z": 0,
            "elements": "ct_machine_frame_steel"
        },
        {
            "x": 0,
            "y": 1,
            "z": 0,
            "elements": "ct_machine_frame_steel"
        },
        {
            "x": -1,
            "y": -1,
            "z": 0,
            "elements": "ct_machine_frame_steel"
        },
        {
            "x": -1,
            "y": 1,
            "z": 1,
            "elements": "ct_machine_frame_steel"
        },
        {
            "x": 0,
            "y": 1,
            "z": 1,
            "elements": [
                "minecraft:glass@0",
                "modularmachinery:blockinputbus",
                "modularmachinery:blockenergyinputhatch",
                "modularmachinery:blockfluidinputhatch",
                "modularmachinery:blockoutputbus"
            ]
        },
        {
            "x": 1,
            "y": 1,
            "z": 0,
            "elements": "ct_machine_frame_steel"
        },
        {
            "x": -1,
            "y": 1,
            "z": 2,
            "elements": "ct_machine_frame_steel"
        },
        {
            "x": 0,
            "y": 1,
            "z": 2,
            "elements": [
                "minecraft:glass@0",
                "modularmachinery:blockinputbus",
                "modularmachinery:blockenergyinputhatch",
                "modularmachinery:blockfluidinputhatch",
                "modularmachinery:blockoutputbus"
            ]
        },
        {
            "x": 1,
            "y": 1,
            "z": 1,
            "elements": "ct_machine_frame_steel"
        },
        {
            "x": -1,
            "y": -1,
            "z": 1,
            "elements": "ct_machine_frame_steel"
        },
        {
            "x": -1,
            "y": 1,
            "z": 3,
            "elements": "ct_machine_frame_steel"
        },
        {
            "x": 0,
            "y": 1,
            "z": 3,
            "elements": "ct_machine_frame_steel"
        },
        {
            "x": 1,
            "y": 1,
            "z": 2,
            "elements": "ct_machine_frame_steel"
        },
        {
            "x": 0,
            "y": -1,
            "z": 1,
            "elements": "ct_agitator_steel"
        },
        {
            "x": -1,
            "y": -1,
            "z": 2,
            "elements": "ct_machine_frame_steel"
        },
        {
            "x": 1,
            "y": 1,
            "z": 3,
            "elements": "ct_machine_frame_steel"
        },
        {
            "x": 0,
            "y": -1,
            "z": 2,
            "elements": "ct_agitator_steel"
        },
        {
            "x": 1,
            "y": -1,
            "z": 1,
            "elements": "ct_machine_frame_steel"
        },
        {
            "x": -1,
            "y": -1,
            "z": 3,
            "elements": "ct_machine_frame_steel"
        },
        {
            "x": 1,
            "y": -1,
            "z": 2,
            "elements": "ct_machine_frame_steel"
        },
        {
            "x": 0,
            "y": -1,
            "z": 3,
            "elements": "ct_machine_frame_steel"
        },
        {
            "x": 1,
            "y": -1,
            "z": 3,
            "elements": "ct_machine_frame_steel"
        }
    ]}