{
    "registryname": "electrolyzer_aluminium", 
    "localizedname": "Aluminium Electrolyzer", 
    "requires-blueprint": true, 
    "color": "80C8F0",  
    "parts": [
        {
            "x": -1,
            "y": 0,
            "z": 1,
            "elements": [
                "minecraft:water@0"
            ]
        },
        {
            "x": -1,
            "y": 0,
            "z": 0,
            "elements": [
                "minecraft:glass@0"
            ]
        },
        {
            "x": 0,
            "y": 0,
            "z": 0,
            "elements": [
                "modularmachinery:blockcontroller@2"
            ]
        },
        {
            "x": -2,
            "y": 0,
            "z": 2,
            "elements": [
                "minecraft:iron_bars@0"
            ]
        },
        {
            "x": 0,
            "y": 0,
            "z": 1,
            "elements": [
                "thermalfoundation:storage@0"
            ]
        },
        {
            "x": -2,
            "y": 0,
            "z": 0,
            "elements": [
                "minecraft:iron_bars@0"
            ]
        },
        {
            "x": 1,
            "y": 0,
            "z": 0,
            "elements": [
                "minecraft:glass@0"
            ]
        },
        {
            "x": -1,
            "y": 0,
            "z": 2,
            "elements": [
                "minecraft:glass@0"
            ]
        },
        {
            "x": 1,
            "y": 0,
            "z": 1,
            "elements": [
                "minecraft:water@0"
            ]
        },
        {
            "x": 2,
            "y": 0,
            "z": 0,
            "elements": [
                "minecraft:iron_bars@0"
            ]
        },
        {
            "x": 0,
            "y": 0,
            "z": 2,
            "elements": [
                "minecraft:glass@0"
            ]
        },
        {
            "x": 1,
            "y": 0,
            "z": 2,
            "elements": [
                "minecraft:glass@0"
            ]
        },
        {
            "x": 2,
            "y": 0,
            "z": 1,
            "elements": [
                "minecraft:iron_bars@0"
            ]
        },
        {
            "x": 2,
            "y": 0,
            "z": 2,
            "elements": [
                "minecraft:iron_bars@0"
            ]
        },
        {
            "x": 2,
            "y": -1,
            "z": 0,
            "elements": ["ct_machine_frame_aluminium", "casings_all"]
        },
        {
            "x": -2,
            "y": 1,
            "z": 0,
            "elements": [
                "minecraft:iron_bars@0"
            ]
        },
        {
            "x": 1,
            "y": -1,
            "z": 0,
            "elements": ["ct_machine_frame_aluminium", "casings_all"]
        },
        {
            "x": -1,
            "y": 1,
            "z": 0,
            "elements": "ct_machine_frame_aluminium"
        },
        {
            "x": 0,
            "y": -1,
            "z": 0,
            "elements": ["ct_machine_frame_aluminium", "casings_all"]
        },
        {
            "x": -2,
            "y": 1,
            "z": 1,
            "elements": [
                "minecraft:iron_bars@0"
            ]
        },
        {
            "x": -1,
            "y": 1,
            "z": 1,
            "elements": [
                "minecraft:iron_bars@0"
            ]
        },
        {
            "x": 0,
            "y": 1,
            "z": 0,
            "elements": "ct_machine_frame_aluminium"
        },
        {
            "x": -1,
            "y": -1,
            "z": 0,
            "elements": ["ct_machine_frame_aluminium", "casings_all"]
        },
        {
            "x": -2,
            "y": 1,
            "z": 2,
            "elements": [
                "minecraft:iron_bars@0"
            ]
        },
        {
            "x": 0,
            "y": 1,
            "z": 1,
            "elements": [
                "minecraft:iron_bars@0"
            ]
        },
        {
            "x": 1,
            "y": 1,
            "z": 0,
            "elements": "ct_machine_frame_aluminium"
        },
        {
            "x": -2,
            "y": -1,
            "z": 0,
            "elements": ["ct_machine_frame_aluminium", "casings_all"]
        },
        {
            "x": -2,
            "y": -1,
            "z": 1,
            "elements": ["ct_machine_frame_aluminium", "casings_all"]
        },
        {
            "x": -1,
            "y": 1,
            "z": 2,
            "elements": "ct_machine_frame_aluminium"
        },
        {
            "x": 1,
            "y": 1,
            "z": 1,
            "elements": [
                "minecraft:iron_bars@0"
            ]
        },
        {
            "x": -1,
            "y": -1,
            "z": 1,
            "elements": ["ct_machine_frame_aluminium", "casings_all"]
        },
        {
            "x": 2,
            "y": 1,
            "z": 0,
            "elements": [
                "minecraft:iron_bars@0"
            ]
        },
        {
            "x": -2,
            "y": -1,
            "z": 2,
            "elements": ["ct_machine_frame_aluminium", "casings_all"]
        },
        {
            "x": 0,
            "y": 1,
            "z": 2,
            "elements": "ct_machine_frame_aluminium"
        },
        {
            "x": 0,
            "y": -1,
            "z": 1,
            "elements": ["ct_machine_frame_aluminium", "casings_all"]
        },
        {
            "x": 1,
            "y": 1,
            "z": 2,
            "elements": "ct_machine_frame_aluminium"
        },
        {
            "x": -1,
            "y": -1,
            "z": 2,
            "elements": ["ct_machine_frame_aluminium", "casings_all"]
        },
        {
            "x": 2,
            "y": 1,
            "z": 1,
            "elements": [
                "minecraft:iron_bars@0"
            ]
        },
        {
            "x": 1,
            "y": -1,
            "z": 1,
            "elements": ["ct_machine_frame_aluminium", "casings_all"]
        },
        {
            "x": 2,
            "y": 1,
            "z": 2,
            "elements": [
                "minecraft:iron_bars@0"
            ]
        },
        {
            "x": 0,
            "y": -1,
            "z": 2,
            "elements": ["ct_machine_frame_aluminium", "casings_all"]
        },
        {
            "x": 1,
            "y": -1,
            "z": 2,
            "elements": ["ct_machine_frame_aluminium", "casings_all"]
        },
        {
            "x": 2,
            "y": -1,
            "z": 1,
            "elements": ["ct_machine_frame_aluminium", "casings_all"]
        },
        {
            "x": 2,
            "y": -1,
            "z": 2,
            "elements": ["ct_machine_frame_aluminium", "casings_all"]
        },
        {
            "x": -2,
            "y": 0,
            "z": 1,
            "elements": [
                "minecraft:iron_bars@0"
            ]
        }
    ]}