{
  "registryname": "it3_steam_boiler", 
  "localizedname": "Bronze Steam Boiler", 
  "requires-blueprint": true, 
  "color": "AA4900",  
	"parts": [{
			"x": -1,
			"y": 0,
			"z": 0,
			"elements": [
				"minecraft:brick_block@0"
			]
		},
		{
			"x": -1,
			"y": 0,
			"z": 1,
			"elements": [
				"minecraft:brick_block@0"
			]
		},
		{
			"x": -1,
			"y": 0,
			"z": 2,
			"elements": [
				"minecraft:brick_block@0"
			]
		},
		{
			"x": 0,
			"y": 0,
			"z": 1,
			"elements": [
				"minecraft:brick_block@0"
			]
		},
		{
			"x": 0,
			"y": 0,
			"z": 2,
			"elements": [
				"minecraft:brick_block@0"
			]
		},
		{
			"x": 1,
			"y": 0,
			"z": 0,
			"elements": [
				"minecraft:brick_block@0"
			]
		},
		{
			"x": 1,
			"y": 0,
			"z": 1,
			"elements": [
				"minecraft:brick_block@0"
			]
		},
		{
			"x": 1,
			"y": 0,
			"z": 2,
			"elements": [
				"minecraft:brick_block@0"
			]
		},
		{
			"x": -1,
			"y": 1,
			"z": 0,
			"elements": [
				"contenttweaker:bronze_plated_brick"
			]
		},
		{
			"x": -1,
			"y": 1,
			"z": 1,
			"elements": ["ct_machine_frame_bronze", "modularmachinery:blockfluidinputhatch", "modularmachinery:blockinputbus"]
		},
		{
			"x": -1,
			"y": 1,
			"z": 2,
			"elements": [
				"contenttweaker:bronze_plated_brick"
			]
		},
		{
			"x": 0,
			"y": 1,
			"z": 0,
			"elements": ["ct_machine_frame_bronze", "modularmachinery:blockfluidinputhatch", "modularmachinery:blockinputbus"]
		},
		{
			"x": 0,
			"y": 1,
			"z": 2,
			"elements": ["ct_machine_frame_bronze", "modularmachinery:blockfluidinputhatch", "modularmachinery:blockinputbus"]
		},
		{
			"x": 1,
			"y": 1,
			"z": 0,
			"elements": [
				"contenttweaker:bronze_plated_brick"
			]
		},
		{
			"x": 1,
			"y": 1,
			"z": 1,
			"elements":  ["ct_machine_frame_bronze", "modularmachinery:blockfluidinputhatch", "modularmachinery:blockinputbus"]
		},
		{
			"x": 1,
			"y": 1,
			"z": 2,
			"elements": [
				"contenttweaker:bronze_plated_brick"
			]
		},
		{
			"x": -1,
			"y": 2,
			"z": 0,
			"elements": [
				"contenttweaker:bronze_plated_brick"
			]
		},
		{
			"x": -1,
			"y": 2,
			"z": 1,
			"elements": ["ct_machine_frame_bronze", "modularmachinery:blockfluidoutputhatch", "modularmachinery:blockoutputbus"]
		},
		{
			"x": -1,
			"y": 2,
			"z": 2,
			"elements": [
				"contenttweaker:bronze_plated_brick"
			]
		},
		{
			"x": 0,
			"y": 2,
			"z": 0,
			"elements": ["ct_machine_frame_bronze", "modularmachinery:blockfluidoutputhatch", "modularmachinery:blockoutputbus"]
		},
		{
			"x": 0,
			"y": 2,
			"z": 2,
			"elements": ["ct_machine_frame_bronze", "modularmachinery:blockfluidoutputhatch", "modularmachinery:blockoutputbus"]
		},
		{
			"x": 1,
			"y": 2,
			"z": 0,
			"elements": [
				"contenttweaker:bronze_plated_brick"
			]
		},
		{
			"x": 1,
			"y": 2,
			"z": 1,
			"elements": ["ct_machine_frame_bronze", "modularmachinery:blockfluidoutputhatch", "modularmachinery:blockoutputbus"]
		},
		{
			"x": 1,
			"y": 2,
			"z": 2,
			"elements": [
				"contenttweaker:bronze_plated_brick"
			]
		},
		{
			"x": -1,
			"y": 3,
			"z": 0,
			"elements": [
				"contenttweaker:bronze_plated_brick"
			]
		},
		{
			"x": -1,
			"y": 3,
			"z": 1,
			"elements": [
				"contenttweaker:bronze_plated_brick"
			]
		},
		{
			"x": -1,
			"y": 3,
			"z": 2,
			"elements": [
				"contenttweaker:bronze_plated_brick"
			]
		},
		{
			"x": 0,
			"y": 3,
			"z": 0,
			"elements": [
				"contenttweaker:bronze_plated_brick"
			]
		},
		{
			"x": 0,
			"y": 3,
			"z": 1,
			"elements": "modularmachinery:blockfluidoutputhatch"
		},
		{
			"x": 0,
			"y": 3,
			"z": 2,
			"elements": [
				"contenttweaker:bronze_plated_brick"
			]
		},
		{
			"x": 1,
			"y": 3,
			"z": 0,
			"elements": [
				"contenttweaker:bronze_plated_brick"
			]
		},
		{
			"x": 1,
			"y": 3,
			"z": 1,
			"elements": [
				"contenttweaker:bronze_plated_brick"
			]
		},
		{
			"x": 1,
			"y": 3,
			"z": 2,
			"elements": [
				"contenttweaker:bronze_plated_brick"
			]
		}
	]
}